Workbook

Sheet 개요
A1: MechDog Dog C 테스트 시나리오 및 테스트 케이스 명세서
A2: Test Scenario & Test Case Sheet
A4: 프로젝트 | B4: MechDog 팀 프로젝트 (2026 미래내일 일경험 - 청년피지컬AI)
A5: 담당 파트 | B5: Dog C - 목적지 유도·에스코트 (+ 팀 DB/인프라)
A6: 작성자 | B6: 최현수
A7: 작성일 / 버전 | B7: 2026-09-28 / v3.0 (오후: 카메라 비전 복귀, 경로 기록 모드, 터치 진단 반영)
A8: 테스트 대상 | B8: 로봇 펌웨어 main_wifi.py / 에스코트 escort_wifi.py / 카메라 추적 ball_vision.py / 경로 기록 record_route.py / ESP32-CAM / MQTT→DB 브릿지
A9: 테스트 환경 | B9: Hiwonder MechDog(ESP32) · ESP32-CAM(OV2640, RGB565, 240x240) · 폰 핫스팟(172.20.10.x, 로봇 .6 / 카메라 .7, UDP 9027) · Windows 노트북 · Docker(PostgreSQL, Mosquitto, bridge)
A10: 테스트 범위 | B10: WiFi 통신, 이동 제어, 로봇 자체 안전장치(Tier1), 카메라 동시작동, 에스코트 주행, 도착 인터랙션, 출발지 복귀, 비상정지, MQTT/DB 연동, 공개 저장소 보안, 카메라 비전 인식
A11: 범위 제외 | B11: A파트(출입인증)·B파트(대화) 연동 통합 테스트 - 팀 통합 테스트 단계에서 별도 수행
A12: 판정 기준 | B12: Pass: 기대 결과와 일치 / Fail: 불일치(결함 등록) / Blocked: 선행 조건 미충족으로 수행 불가 / Not Run: 미수행
A13: 시트 구성 | B13: ① 테스트 시나리오 ② 테스트 케이스 ③ 결과 요약(자동 집계) ④ 결함 목록
A14: 작성 방법 | B14: 테스트 케이스 시트의 '실제 결과', '판정', '실행일' 칸만 입력하면 결과 요약이 자동 갱신됨. 판정은 목록에서 선택

Sheet 테스트 시나리오
A1: 시나리오 ID | B1: 시나리오명 | C1: 목적 | D1: 우선순위 | E1: 케이스 수
A2: TS-01 | B2: WiFi 통신 연결 | C2: 로봇이 폰 핫스팟에 접속하고 노트북과 UDP로 명령/응답을 주고받는지 확인 | D2: 상 | E2: =COUNTIF('테스트 케이스'!$B:$B,A2) -> 4
A3: TS-02 | B3: 이동 제어 | C3: WiFi 명령으로 이동·정지가 신뢰성 있게 동작하는지 확인 (keepalive 포함) | D3: 상 | E3: =COUNTIF('테스트 케이스'!$B:$B,A3) -> 3
A4: TS-03 | B4: 로봇 자체 안전장치(Tier1) | C4: 노트북과 무관하게 로봇 스스로 위험 상황에서 정지하는지 확인 | D4: 상 | E4: =COUNTIF('테스트 케이스'!$B:$B,A4) -> 3
A5: TS-04 | B5: 카메라 스트리밍 | C5: ESP32-CAM 영상이 로봇 구동 중에도 안정적으로 유지되는지 확인 | D5: 중 | E5: =COUNTIF('테스트 케이스'!$B:$B,A5) -> 4
A6: TS-05 | B6: 에스코트 주행 | C6: 목적지까지 웨이포인트 주행과 장애물 회피가 동작하는지 확인 | D6: 상 | E6: =COUNTIF('테스트 케이스'!$B:$B,A6) -> 4
A7: TS-06 | B7: 도착 인터랙션 | C7: 도착 인사 동작과 터치센서 기반 다음 단계 전환이 동작하는지 확인 | D7: 중 | E7: =COUNTIF('테스트 케이스'!$B:$B,A7) -> 6
A8: TS-07 | B8: 출발지 복귀 | C8: 안내 후 출발지로 돌아와 다음 안내 준비 상태가 되는지 확인 | D8: 상 | E8: =COUNTIF('테스트 케이스'!$B:$B,A8) -> 7
A9: TS-08 | B9: 비상정지 | C9: 사용자가 이동 중 즉시 정지시킬 수 있는지 확인 | D9: 상 | E9: =COUNTIF('테스트 케이스'!$B:$B,A9) -> 2
A10: TS-09 | B10: MQTT/DB 연동 | C10: 에스코트 상태·경고가 팀 표준 토픽으로 발행되고 DB에 저장되는지 확인 | D10: 중 | E10: =COUNTIF('테스트 케이스'!$B:$B,A10) -> 3
A11: TS-10 | B11: 공개 저장소 보안 | C11: GitHub 공개 저장소에 비밀번호·개인정보가 올라가지 않는지 확인 | D11: 중 | E11: =COUNTIF('테스트 케이스'!$B:$B,A11) -> 2
A12: TS-11 | B12: 카메라 비전 인식 | C12: 로봇 카메라(저시점·240x240)로 출발지 표식을 안정적으로 인식하는지 확인 | D12: 중 | E12: =COUNTIF('테스트 케이스'!$B:$B,A12) -> 5

Sheet 테스트 케이스
A1: TC ID | B1: 시나리오 ID | C1: 테스트 항목 | D1: 사전 조건 | E1: 테스트 절차 | F1: 입력 데이터 | G1: 기대 결과 | H1: 실제 결과 | I1: 판정 | J1: 실행일 | K1: 비고 / 결함 ID
A2: TC-001 | B2: TS-01 | C2: 로봇 핫스팟 접속 | D2: 폰 핫스팟 '호환성 최대화' ON, 로봇에 main_wifi.py 업로드 | E2: 1. 로봇 전원 ON 2. 시리얼 로그 확인 | F2: - | G2: 'Socket setup success' 출력, IP 할당 | H2: IP 172.20.10.6 할당, 소켓 준비 완료 (1차 timeout 후 재시도로 연결) | I2: Pass | J2: 2026-09-28
A3: TC-002 | B3: TS-01 | C3: 배터리 조회 응답 | D3: TC-001 통과, 노트북 동일 핫스팟 접속 | E3: escort_wifi.py 실행 (시작 시 자동 조회) | F3: CMD|6|$ | G3: 'CMD|6|{값}|$' 응답 수신 | H3: '배터리: 12704.0' 수신 (mV 단위, 12.7V) | I3: Pass | J3: 2026-09-28
A4: TC-003 | B4: TS-01 | C4: 거리센서 조회 응답 | D4: TC-001 통과 | E4: 에스코트 이동 중 자동 조회 (0.25초 주기) | F4: CMD|4|1|$ | G4: 'CMD|4|{cm×10}|$' 응답, 장애물 판단에 사용 | H4: 응답 수신, 장애물 감지 로직 정상 동작 | I4: Pass | J4: 2026-09-28
A5: TC-004 | B5: TS-01 | C5: 터치센서 조회 응답 | D5: TC-001 통과 | E5: 도착 후 터치센서 누름 | F5: CMD|11|1|$ | G5: 'CMD|11|1|$' 응답 후 로봇 측 플래그 리셋 | H5: '터치 확인!' 출력, 즉시 복귀 단계 진입 | I5: Pass | J5: 2026-09-28
A6: TC-005 | B6: TS-02 | C6: 단시간 직진·정지 | D6: TC-001 통과, 전방 1m 확보 | E6: wifi_move_test.py (2초 설정) 실행 | F6: CMD|3|3|$ → CMD|3|0|$ | G6: 2초 직진 후 정지 | H6: 정상 동작 (이동 루프 CPU 양보 수정 후) | I6: Pass | J6: 2026-09-23 | K6: 이전 세션: 이동 루프 CPU 양보(sleep 0.01) 수정 후 통과
A7: TC-006 | B7: TS-02 | C7: keepalive 연속 이동 | D7: TC-001 통과, 전방 3m 확보, 카메라 스트리밍 ON | E7: wifi_move_test.py (WATCHDOG_TEST=False) 실행 | F7: 5초 직진 × 3회, 0.3초 재전송 | G7: 매회 5초 끝까지 이동 후 정지, 중간 끊김 없음 | H7: 3회 모두 5초 이동 (회당 명령 18회 전송), 정상 정지 | I7: Pass | J7: 2026-09-28
A8: TC-007 | B8: TS-02 | C8: 정지 명령 신뢰성 | D8: TC-006 수행 중 | E8: 이동 종료 시 정지 명령 3회 전송 확인 | F8: CMD|3|0|$ × 3 | G8: UDP 유실 없이 즉시 정지 | H8: 매회 정상 정지 | I8: Pass | J8: 2026-09-28 | K8: UDP 유실 대비 3회 전송 설계
A9: TC-008 | B9: TS-03 | C9: 통신두절 자동정지 | D9: 수정된 main_wifi.py 업로드 | E9: wifi_move_test.py (WATCHDOG_TEST=True): 이동 명령 1회만 전송 | F9: CMD|3|3|$ 1회 | G9: 명령 끊긴 후 약 1초 내 로봇 스스로 정지 | H9: 약 1초 후 자동 정지 확인 (3회) | I9: Pass | J9: 2026-09-28 | K9: D-001, D-002 수정 후 통과
A10: TC-009 | B10: TS-03 | C10: 근접 즉시정지 (전진) | D10: 전방 10cm 이내에 장애물 배치 | E10: 전진 명령 keepalive로 지속 전송 | F10: CMD|3|3|$ 반복 | G10: 거리 10cm 미만 시 로봇 스스로 정지 | I10: Not Run | K10: 에스코트 회피(15cm)가 먼저 동작하므로 별도 테스트 필요
A11: TC-010 | B11: TS-03 | C11: 근접 상태 후진 허용 | D11: 로봇 전방 10cm 이내 장애물 | E11: 후진 명령 전송 | F11: CMD|3|7|$ | G11: 근접정지에 막히지 않고 후진 가능 (회피 동작 보장) | I11: Not Run
A12: TC-011 | B12: TS-04 | C12: 브라우저 스트리밍 접속 | D12: 카메라 핫스팟 접속 (172.20.10.7) | E12: 브라우저에서 http://172.20.10.7 접속 → Start Stream | F12: - | G12: 실시간 영상 표시 | H12: 영상 정상 표시 | I12: Pass | J12: 2026-09-28 | K12: RGB565 모드 (센서 JPEG 설정 미적용)
A13: TC-012 | B13: TS-04 | C13: 영상 방향 보정 | D13: TC-011 통과 | E13: V-Flip 설정 적용 | F13: - | G13: 영상 상하 방향 정상 | H13: 정상 방향으로 보정 | I13: Pass | J13: 2026-09-28 | K13: 펌웨어 코드에 고정 여부 확인 필요
A14: TC-013 | B14: TS-04 | C14: 로봇 구동 중 동시작동 | D14: TC-011 통과, 카메라·로봇·노트북 동일 핫스팟 | E14: 스트리밍 켠 상태로 TC-006 수행 | F14: 5초 × 3회 이동 | G14: 영상 끊김·카메라 리셋 없음 | H14: 영상 유지, 리셋 없음 | I14: Pass | J14: 2026-09-28 | K14: 이전 BLE+카메라 핫스팟 환경의 리셋 문제 해소
A15: TC-014 | B15: TS-04 | C15: 장시간 안정성 | D15: TC-013 통과 | E15: 스트리밍 유지 + 주기적 이동 명령, 10분 | F15: - | G15: 10분간 영상·명령 모두 유지 | I15: Not Run
A16: TC-015 | B16: TS-05 | C16: 웨이포인트 목적지 이동 | D16: docker compose up, escort_wifi.py 실행 | E16: 목적지 'lobby' 입력 | F16: lobby (직진 3초) | G16: 경로대로 이동 후 '도착' 출력 | H16: 정상 도착 (3회 수행) | I16: Pass | J16: 2026-09-28
A17: TC-016 | B17: TS-05 | C17: 장애물 감지 및 회피 | D17: 전방 경로에 장애물 배치 | E17: 목적지 이동 중 장애물 접근 | F17: OBSTACLE_THRESHOLD 15cm | G17: 감지 → S자 회피 → 원래 방향으로 이동 재개 | H17: 10cm 감지 → 1차 회피 성공 → 이동 재개 | I17: Pass | J17: 2026-09-28 | K17: 장애물 실물 유무 기록 필요 (오감지 여부)
A18: TC-017 | B18: TS-05 | C18: 회피 반복 실패 시 중단 | D18: 넓은 벽 등 회피 불가 장애물 | E18: 목적지 이동 중 벽 접근 | F18: MAX_AVOID_ATTEMPTS 4 | G18: 4회 실패 시 에스코트 중단, escort_lost 경고 발행, 남은 경로 미진행 | I18: Not Run | K18: 가상 로봇 시뮬레이션만 확인 (D-006 수정분)
A19: TC-018 | B19: TS-05 | C19: 다중 스텝 경로 | D19: TC-015 통과 | E19: 목적지 'room_a', 'room_b' 입력 | F19: 직진+회전 조합 | G19: 각 스텝 순서대로 수행 후 도착 | I19: Not Run
A20: TC-019 | B20: TS-06 | C20: 도착 인사 동작 | D20: TC-015 통과 | E20: 목적지 도착 대기 | F20: CMD|2|1|8|$ | G20: scrape_a_bow 동작 재생 | H20: 1회 누락 발생 → 원인 수정 후 재시험 필요 | I20: Fail | J20: 2026-09-28 | K20: D-003, D-004
A21: TC-020 | B21: TS-06 | C21: 터치 시 즉시 복귀 | D21: 도착 후 대기 상태 | E21: 8초 이내 터치센서 누름 | F21: - | G21: '터치 확인!' 후 즉시 복귀 시작 | H21: 터치하지 않았는데 '터치 확인!' 출력 (오감지) - 초기 Pass 판정 정정 | I21: Fail | J21: 2026-09-28 | K21: D-011
A22: TC-021 | B22: TS-06 | C22: 터치 없음 타임아웃 | D22: 도착 후 대기 상태 | E22: 터치하지 않고 대기 | F22: DWELL_SECONDS 8 | G22: 8초 후 자동으로 복귀 시작 | H22: '시간 초과로 복귀' 출력 후 복귀 | I22: Pass | J22: 2026-09-28
A23: TC-022 | B23: TS-06 | C23: 도착 전 터치 기록 무시 | D23: 이동 중 터치센서 누름 | E23: 이동 중 터치 → 도착 후 대기 | F23: - | G23: 도착 전 터치는 무시, 도착 후 터치만 인정 | I23: Not Run | K23: D-009 수정분
A24: TC-023 | B24: TS-07 | C24: 출발지 복귀 위치 | D24: TC-015 통과 | E24: 도착·대기 후 복귀 과정 관찰 | F24: lobby | G24: 출발 위치 근처로 복귀 후 idle | H24: 방향 전환 없이 같은 방향으로 3초 더 전진 (출발지에서 약 1.3m 이탈) | I24: Fail | J24: 2026-09-28 | K24: D-005
A25: TC-024 | B25: TS-07 | C25: U턴 (강좌회전 이동) | D25: D-005 조치 적용 | E25: 목적지 입력에 'uturn' 입력 | F25: dir 5, 4.5초 | G25: 반경 작게 약 180도 전환 | H25: 회전 반경이 너무 커서 출발지 복귀 불가 | I25: Fail | J25: 2026-09-28 | K25: D-007
A26: TC-025 | B26: TS-07 | C26: K턴 방향 전환 | D26: 후진 회전(dir 6/8) 방향 실측 완료 | E26: 전진좌회전·후진회전 교대 반복 | F26: TBD | G26: 좁은 공간에서 약 180도 전환 | I26: Not Run | K26: 경로 기록 모드(TC-037) 도입으로 보류
A27: TC-026 | B27: TS-08 | C27: 'q' 키 비상정지 | D27: 에스코트 이동 중 | E27: 키보드 q 입력 (Enter 없이) | F27: q | G27: 즉시 정지, emergency_stop 경고 발행 | I27: Not Run
A28: TC-027 | B28: TS-08 | C28: Ctrl+C 종료 시 정지 | D28: 에스코트 이동 중 | E28: Ctrl+C 입력 | F28: - | G28: 정지 명령 전송 후 안전 종료 | I28: Not Run
A29: TC-028 | B29: TS-09 | C29: escort.status 발행·저장 | D29: Docker 3개 컨테이너 실행 | E29: 에스코트 1회 수행 후 event_logs 조회 | F29: idle/moving/arrived | G29: 상태 변화마다 발행(retain), 이동 중 1Hz, DB 저장 | H29: MQTT 연결 확인, DB 저장 미확인 | I29: Not Run | K29: check_recent_events.py로 확인 예정
A30: TC-029 | B30: TS-09 | C30: alert.event 저장 (detail 포함) | D30: TC-030 통과 | E30: escort_lost 또는 emergency_stop 발생 | F30: reason, detail | G30: alert_logs에 detail 포함 1행 저장 | I30: Not Run
A31: TC-030 | B31: TS-09 | C31: alert_logs.detail 스키마 반영 | D31: PostgreSQL 컨테이너 실행 | E31: migration SQL을 docker cp 방식으로 실행 후 \d+ alert_logs | F31: migration_20260927_alert_detail.sql | G31: detail 컬럼 존재, 한글 설명 정상 | H31: 컬럼 존재(기존), 한글 설명 정상 반영 | I31: Pass | J31: 2026-09-28 | K31: D-008 조치 후 통과
A32: TC-031 | B32: TS-10 | C32: 커밋 이력 비밀번호 검사 | D32: git 저장소 | E32: git log -p -S "<비밀번호>" | F32: - | G32: 검색 결과 없음 | H32: 결과 없음 (이력에 비밀번호 없음) | I32: Pass | J32: 2026-09-28
A33: TC-032 | B33: TS-10 | C33: 커밋 대상 파일 비밀번호 검사 | D33: 푸시 직전 | E33: Select-String으로 main_wifi.py 등 검사 | F33: WiFi 이름/비밀번호 | G33: 검색 결과 없음 (자리표시자만 존재) | H33: 1차 검사 시 비밀번호 발견 → 푸시 보류 | I33: Fail | J33: 2026-09-28 | K33: D-010 (자리표시자 버전으로 교체 후 재검사)
A34: TC-033 | B34: TS-06 | C34: 터치센서 단독 진단 | D34: 로봇 정지 상태 | E34: escort_wifi.py 'touch' 명령: 10초 미접촉 → 10초 누르기 | F34: 0.5초 간격 조회 40회 | G34: 미접촉 구간 0회, 누를 때만 '눌림' | H34: 미접촉 0회, 누를 때만 감지 (센서 정상) | I34: Pass | J34: 2026-09-28 | K34: D-011 원인 분리: 하드웨어 아님
A35: TC-034 | B35: TS-06 | C35: 인사 동작 진동 오감지 | D35: 로봇 정지 상태, 터치 금지 | E35: 'bow' 명령: 인사 동작 후 터치 기록 확인 | F35: CMD|2|1|8|$ | G35: 인사 후 터치 기록 없음 | H35: 없음 (진동 오감지 없음) | I35: Pass | J35: 2026-09-28
A36: TC-035 | B36: TS-07 | C36: 카메라 복귀 (공 정면) | D36: 초록 공이 로봇 정면 약 1m | E36: 'home' 명령 | F36: R_STOP 13px | G36: 좌우 보정하며 접근 후 공 앞 약 50cm 정지 | H36: 공 발견 → 좌/직/우 보정 → r=14.0px에서 정지 | I36: Pass | J36: 2026-09-28
A37: TC-036 | B37: TS-07 | C37: 카메라 복귀 (공 측면, 탐색) | D37: 초록 공이 로봇 옆 약 1m | E37: 'home' 명령 (제자리 회전 탐색) | F37: SPIN_COUNT 40, 최대 16회 | G37: 탐색으로 공 발견 후 접근·정지 | H37: 공을 보고도 지나치거나 정렬 후 놓침 반복 → 미발견 종료 | I37: Fail | J37: 2026-09-28 | K37: D-014, D-015
A38: TC-037 | B38: TS-07 | C38: 경로 기록 모드 | D38: 로봇 출발지 위치 | E38: record_route.py로 가는 길/돌아오는 길 키보드 주행 기록 | F38: meeting_room_1 | G38: destinations.json에 팀 목적지 코드로 저장 | H38: 1개 목적지 기록 완료 | I38: Pass | J38: 2026-09-28 | K38: D-007 대체 방안
A39: TC-038 | B39: TS-07 | C39: 기록 경로 재생 정확도 | D39: TC 경로 기록 완료, 출발/도착 지점 테이프 표시 | E39: escort_wifi.py로 기록 경로 3회 재생 | F39: meeting_room_1 | G39: 도착·복귀 오차 일정 범위 이내, 3회 편차 작음 | H39: 1회차 진행 중 로봇 배터리 방전 | I39: Blocked | J39: 2026-09-28 | K39: 충전 후 재시험
A40: TC-039 | B40: TS-11 | C40: YOLO 기본 모델 목표물 인식 | D40: 노트북에서 로봇 카메라 스트림 수신 | E40: yolo_stream_test.py로 스툴/텀블러/가방 인식 (0.5~1.5m) | F40: yolov8n, yolov8s | G40: 목표물을 올바른 이름으로 인식 | H40: 스툴 근거리만 0.38, 텀블러→냉장고, 가방→소파 등 오인식 다수 | I40: Fail | J40: 2026-09-28 | K40: D-012 (색깔 공 방식으로 전환)
...

Sheet 결과 요약
A1: 시나리오 ID | B1: 시나리오명 | C1: 전체 | D1: Pass | E1: Fail | F1: Blocked | G1: Not Run | H1: 수행률 | I1: 통과율
A2: ='테스트 시나리오'!A2 -> TS-01 | B2: ='테스트 시나리오'!B2 -> WiFi 통신 연결 | C2: =COUNTIF('테스트 케이스'!$B:$B,A2) -> 4 | D2: =COUNTIFS('테스트 케이스'!$B:$B,A2,'테스트 케이스'!$I:$I,"Pass") -> 4 | E2: =COUNTIFS('테스트 케이스'!$B:$B,A2,'테스트 케이스'!$I:$I,"Fail") -> 0 | F2: =COUNTIFS('테스트 케이스'!$B:$B,A2,'테스트 케이스'!$I:$I,"Blocked") -> 0 | G2: =COUNTIFS('테스트 케이스'!$B:$B,A2,'테스트 케이스'!$I:$I,"Not Run") -> 0 | H2: =IF(C2=0,0,(C2-F2-G2)/C2) -> 1 | I2: =IF((C2-F2-G2)=0,0,D2/(C2-F2-G2)) -> 1
A3: ='테스트 시나리오'!A3 -> TS-02 | B3: ='테스트 시나리오'!B3 -> 이동 제어 | C3: =COUNTIF('테스트 케이스'!$B:$B,A3) -> 3 | D3: =COUNTIFS('테스트 케이스'!$B:$B,A3,'테스트 케이스'!$I:$I,"Pass") -> 3 | E3: =COUNTIFS('테스트 케이스'!$B:$B,A3,'테스트 케이스'!$I:$I,"Fail") -> 0 | F3: =COUNTIFS('테스트 케이스'!$B:$B,A3,'테스트 케이스'!$I:$I,"Blocked") -> 0 | G3: =COUNTIFS('테스트 케이스'!$B:$B,A3,'테스트 케이스'!$I:$I,"Not Run") -> 0 | H3: =IF(C3=0,0,(C3-F3-G3)/C3) -> 1 | I3: =IF((C3-F3-G3)=0,0,D3/(C3-F3-G3)) -> 1
A4: ='테스트 시나리오'!A4 -> TS-03 | B4: ='테스트 시나리오'!B4 -> 로봇 자체 안전장치(Tier1) | C4: =COUNTIF('테스트 케이스'!$B:$B,A4) -> 3 | D4: =COUNTIFS('테스트 케이스'!$B:$B,A4,'테스트 케이스'!$I:$I,"Pass") -> 1 | E4: =COUNTIFS('테스트 케이스'!$B:$B,A4,'테스트 케이스'!$I:$I,"Fail") -> 0 | F4: =COUNTIFS('테스트 케이스'!$B:$B,A4,'테스트 케이스'!$I:$I,"Blocked") -> 0 | G4: =COUNTIFS('테스트 케이스'!$B:$B,A4,'테스트 케이스'!$I:$I,"Not Run") -> 2 | H4: =IF(C4=0,0,(C4-F4-G4)/C4) -> 0.33333333 | I4: =IF((C4-F4-G4)=0,0,D4/(C4-F4-G4)) -> 1
A5: ='테스트 시나리오'!A5 -> TS-04 | B5: ='테스트 시나리오'!B5 -> 카메라 스트리밍 | C5: =COUNTIF('테스트 케이스'!$B:$B,A5) -> 4 | D5: =COUNTIFS('테스트 케이스'!$B:$B,A5,'테스트 케이스'!$I:$I,"Pass") -> 3 | E5: =COUNTIFS('테스트 케이스'!$B:$B,A5,'테스트 케이스'!$I:$I,"Fail") -> 0 | F5: =COUNTIFS('테스트 케이스'!$B:$B,A5,'테스트 케이스'!$I:$I,"Blocked") -> 0 | G5: =COUNTIFS('테스트 케이스'!$B:$B,A5,'테스트 케이스'!$I:$I,"Not Run") -> 1 | H5: =IF(C5=0,0,(C5-F5-G5)/C5) -> 0.75 | I5: =IF((C5-F5-G5)=0,0,D5/(C5-F5-G5)) -> 1
A6: ='테스트 시나리오'!A6 -> TS-05 | B6: ='테스트 시나리오'!B6 -> 에스코트 주행 | C6: =COUNTIF('테스트 케이스'!$B:$B,A6) -> 4 | D6: =COUNTIFS('테스트 케이스'!$B:$B,A6,'테스트 케이스'!$I:$I,"Pass") -> 2 | E6: =COUNTIFS('테스트 케이스'!$B:$B,A6,'테스트 케이스'!$I:$I,"Fail") -> 0 | F6: =COUNTIFS('테스트 케이스'!$B:$B,A6,'테스트 케이스'!$I:$I,"Blocked") -> 0 | G6: =COUNTIFS('테스트 케이스'!$B:$B,A6,'테스트 케이스'!$I:$I,"Not Run") -> 2 | H6: =IF(C6=0,0,(C6-F6-G6)/C6) -> 0.5 | I6: =IF((C6-F6-G6)=0,0,D6/(C6-F6-G6)) -> 1
A7: ='테스트 시나리오'!A7 -> TS-06 | B7: ='테스트 시나리오'!B7 -> 도착 인터랙션 | C7: =COUNTIF('테스트 케이스'!$B:$B,A7) -> 6 | D7: =COUNTIFS('테스트 케이스'!$B:$B,A7,'테스트 케이스'!$I:$I,"Pass") -> 3 | E7: =COUNTIFS('테스트 케이스'!$B:$B,A7,'테스트 케이스'!$I:$I,"Fail") -> 2 | F7: =COUNTIFS('테스트 케이스'!$B:$B,A7,'테스트 케이스'!$I:$I,"Blocked") -> 0 | G7: =COUNTIFS('테스트 케이스'!$B:$B,A7,'테스트 케이스'!$I:$I,"Not Run") -> 1 | H7: =IF(C7=0,0,(C7-F7-G7)/C7) -> 0.83333333 | I7: =IF((C7-F7-G7)=0,0,D7/(C7-F7-G7)) -> 0.6
A8: ='테스트 시나리오'!A8 -> TS-07 | B8: ='테스트 시나리오'!B8 -> 출발지 복귀 | C8: =COUNTIF('테스트 케이스'!$B:$B,A8) -> 7 | D8: =COUNTIFS('테스트 케이스'!$B:$B,A8,'테스트 케이스'!$I:$I,"Pass") -> 2 | E8: =COUNTIFS('테스트 케이스'!$B:$B,A8,'테스트 케이스'!$I:$I,"Fail") -> 3 | F8: =COUNTIFS('테스트 케이스'!$B:$B,A8,'테스트 케이스'!$I:$I,"Blocked") -> 1 | G8: =COUNTIFS('테스트 케이스'!$B:$B,A8,'테스트 케이스'!$I:$I,"Not Run") -> 1 | H8: =IF(C8=0,0,(C8-F8-G8)/C8) -> 0.71428571 | I8: =IF((C8-F8-G8)=0,0,D8/(C8-F8-G8)) -> 0.4
A9: ='테스트 시나리오'!A9 -> TS-08 | B9: ='테스트 시나리오'!B9 -> 비상정지 | C9: =COUNTIF('테스트 케이스'!$B:$B,A9) -> 2 | D9: =COUNTIFS('테스트 케이스'!$B:$B,A9,'테스트 케이스'!$I:$I,"Pass") -> 0 | E9: =COUNTIFS('테스트 케이스'!$B:$B,A9,'테스트 케이스'!$I:$I,"Fail") -> 0 | F9: =COUNTIFS('테스트 케이스'!$B:$B,A9,'테스트 케이스'!$I:$I,"Blocked") -> 0 | G9: =COUNTIFS('테스트 케이스'!$B:$B,A9,'테스트 케이스'!$I:$I,"Not Run") -> 2 | H9: =IF(C9=0,0,(C9-F9-G9)/C9) -> 0 | I9: =IF((C9-F9-G9)=0,0,D9/(C9-F9-G9)) -> 0
A10: ='테스트 시나리오'!A10 -> TS-09 | B10: ='테스트 시나리오'!B10 -> MQTT/DB 연동 | C10: =COUNTIF('테스트 케이스'!$B:$B,A10) -> 3 | D10: =COUNTIFS('테스트 케이스'!$B:$B,A10,'테스트 케이스'!$I:$I,"Pass") -> 1 | E10: =COUNTIFS('테스트 케이스'!$B:$B,A10,'테스트 케이스'!$I:$I,"Fail") -> 0 | F10: =COUNTIFS('테스트 케이스'!$B:$B,A10,'테스트 케이스'!$I:$I,"Blocked") -> 0 | G10: =COUNTIFS('테스트 케이스'!$B:$B,A10,'테스트 케이스'!$I:$I,"Not Run") -> 2 | H10: =IF(C10=0,0,(C10-F10-G10)/C10) -> 0.33333333 | I10: =IF((C10-F10-G10)=0,0,D10/(C10-F10-G10)) -> 1
A11: ='테스트 시나리오'!A11 -> TS-10 | B11: ='테스트 시나리오'!B11 -> 공개 저장소 보안 | C11: =COUNTIF('테스트 케이스'!$B:$B,A11) -> 2 | D11: =COUNTIFS('테스트 케이스'!$B:$B,A11,'테스트 케이스'!$I:$I,"Pass") -> 1 | E11: =COUNTIFS('테스트 케이스'!$B:$B,A11,'테스트 케이스'!$I:$I,"Fail") -> 1 | F11: =COUNTIFS('테스트 케이스'!$B:$B,A11,'테스트 케이스'!$I:$I,"Blocked") -> 0 | G11: =COUNTIFS('테스트 케이스'!$B:$B,A11,'테스트 케이스'!$I:$I,"Not Run") -> 0 | H11: =IF(C11=0,0,(C11-F11-G11)/C11) -> 1 | I11: =IF((C11-F11-G11)=0,0,D11/(C11-F11-G11)) -> 0.5
A12: ='테스트 시나리오'!A12 -> TS-11 | B12: ='테스트 시나리오'!B12 -> 카메라 비전 인식 | C12: =COUNTIF('테스트 케이스'!$B:$B,A12) -> 5 | D12: =COUNTIFS('테스트 케이스'!$B:$B,A12,'테스트 케이스'!$I:$I,"Pass") -> 3 | E12: =COUNTIFS('테스트 케이스'!$B:$B,A12,'테스트 케이스'!$I:$I,"Fail") -> 2 | F12: =COUNTIFS('테스트 케이스'!$B:$B,A12,'테스트 케이스'!$I:$I,"Blocked") -> 0 | G12: =COUNTIFS('테스트 케이스'!$B:$B,A12,'테스트 케이스'!$I:$I,"Not Run") -> 0 | H12: =IF(C12=0,0,(C12-F12-G12)/C12) -> 1 | I12: =IF((C12-F12-G12)=0,0,D12/(C12-F12-G12)) -> 0.6
A13: 합계 | C13: =SUM(C2:C12) -> 43 | D13: =SUM(D2:D12) -> 23 | E13: =SUM(E2:E12) -> 8 | F13: =SUM(F2:F12) -> 1 | G13: =SUM(G2:G12) -> 11 | H13: =IF(C13=0,0,(C13-F13-G13)/C13) -> 0.72093023 | I13: =IF((C13-F13-G13)=0,0,D13/(C13-F13-G13)) -> 0.74193548
A15: ※ 수행률 = (전체 − Blocked − Not Run) ÷ 전체 / 통과율 = Pass ÷ 수행한 케이스 (Blocked·Not Run 제외). 모두 테스트 케이스 시트에서 자동 집계

Sheet 결함 목록
A1: 결함 ID | B1: 발견일 | C1: 관련 TC | D1: 증상 | E1: 원인 | F1: 조치 내용 | G1: 상태
A2: D-001 | B2: 2026-09-28 | C2: TC-008 | D2: 통신두절·근접 정지가 실제로 동작하지 않음 | E2: 안전장치가 move(0,0)만 호출 → 이동 루프가 _RUN_DIR을 보고 즉시 재이동하여 덮어씀 | F2: 정지 시 _RUN_DIR=0으로 이동 상태 자체를 해제, 노트북 측 keepalive 도입 | G2: 종료
A3: D-002 | B3: 2026-09-28 | C3: TC-008 | D3: 통신두절 타임아웃이 1~2초 사이로 부정확 | E3: MicroPython time.time()이 1초 단위 정수 | F3: time.ticks_ms()/ticks_diff()로 변경 (ms 단위) | G3: 종료
A4: D-003 | B4: 2026-09-28 | C4: TC-019 | D4: WiFi 펌웨어에서 인사 동작 미실행 가능 | E4: action_run("8")처럼 번호를 그대로 전달 (BLE 버전은 동작 이름으로 변환) | F4: 번호→동작 이름 매핑(BUILTIN_ACTIONS) 추가 | G4: 재시험 대기
A5: D-004 | B5: 2026-09-28 | C5: TC-019 | D5: 도착 인사 명령이 간헐적으로 누락 | E5: 정지 명령 3회 직후 인사 명령 전송 → 펌웨어의 명령 대기 변수가 덮어써짐 | F5: 정지 후 0.5초 대기 후 인사 명령 전송 | G5: 재시험 대기
A6: D-005 | B6: 2026-09-28 | C6: TC-023 | D6: 복귀 시 출발지 반대 방향으로 전진 | E6: 복귀 경로(역순+좌우반전)가 180도 전환을 전제로 하나 전환 동작 없음 (BLE 버전부터 존재) | F6: U턴 단계 추가 후(D-007) → 경로 기록 모드로 복귀 경로를 직접 기록하는 방식으로 대체 | G6: 재시험 대기
A7: D-006 | B7: 2026-09-28 | C7: TC-017 | D7: 회피 4회 실패 후에도 남은 경로·도착 인사까지 진행 (BLE 버전) | E7: 실패 시 해당 스텝만 return하고 상위 루프가 계속 진행 | F7: EscortLost 예외로 에스코트 전체 중단 | G7: 재시험 대기
A8: D-007 | B8: 2026-09-28 | C8: TC-024 | D8: U턴 반경이 커서 출발지 복귀 불가 | E8: 강좌회전(dir 5)은 전진하며 도는 동작이라 회전 반경 큼, 제자리 회전(CMD|9)은 과거 실험에서 불안정 | F8: 경로 기록 모드(record_route.py)로 복귀 경로를 직접 기록하는 방식으로 대체 | G8: 재시험 대기
A9: D-008 | B9: 2026-09-28 | C9: TC-030 | D9: alert_logs.detail 컬럼 설명 한글 깨짐 (??) | E9: PowerShell 파이프가 네이티브 명령에 한글을 ?로 변환 | F9: docker cp로 컨테이너에 복사 후 psql -f 실행 | G9: 종료
A10: D-009 | B10: 2026-09-28 | C10: TC-022 | D10: 도착 전에 눌린 터치로 즉시 복귀할 가능성 | E10: 로봇 터치 플래그가 조회 전까지 유지됨 | F10: 대기 시작 시 터치 기록 1회 조회로 초기화 | G10: 재시험 대기
A11: D-010 | B11: 2026-09-28 | C11: TC-032 | D11: 커밋 대상 파일에 WiFi 비밀번호 포함 | E11: 업로드용 값을 프로젝트 파일에 직접 입력 | F11: wifi_config.py 분리(.gitignore), 업로드용 복사본은 저장소 밖 보관 | G11: 조치 중
A12: D-011 | B12: 2026-09-28 | C12: TC-020 | D12: 터치하지 않았는데 '터치 확인!' 출력 | E12: 터치센서 정상 확인(진단 TC). 이전 조회의 늦은 응답을 다음 조회 결과로 읽은 것으로 추정 | F12: 터치 기록 초기화 시 0.5초 대기 후 응답 버퍼 비움 | G12: 재시험 대기
... A17: D-016 | B17: 2026-09-28 | C17: TC-043 | D17: 카메라 자동노출·화이트밸런스 설정 불가 | E17: 센서가 해당 설정 미지원 (HTTP 500). 표시상 OV2640이나 실제 센서 상이 추정 | F17: 노트북에서 소프트웨어 밝기 보정 적용 | G17: 종료(우회)
